<?xml version="1.0"?>
<robot xmlns:xacro="http://www.ros.org/wiki/xacro" name="simple_bot">

  <xacro:include filename="inertial_macros.xacro"/>

  <material name="red">
    <color rgba="1 0 0 1"/>
  </material>

  <!-- Properties for easy modification -->
  <xacro:property name="wheel_radius" value="0.08" /> <!-- 3 inches / 2 -->
  <xacro:property name="wheel_width" value="0.03" /> <!-- Assuming a wheel width of 5cm -->
  <xacro:property name="chassis_radius" value="0.25" /> <!-- 10 inches / 2 -->
  <xacro:property name="chassis_height" value="0.05" /> <!-- Assuming a chassis height of 10cm -->

  <!-- Base Link -->
  <link name="base_link">

  </link>

  <!-- Chassis Link -->

  <joint name="chassis_joint" type="fixed">
    <parent link="base_link"/>
    <child link="chassis"/>
    <origin xyz="0 0 0"/>
  </joint>

  <link name="chassis">
    <visual>
      <geometry>
        <cylinder radius="${chassis_radius}" length="${chassis_height}"/>
      </geometry>
    </visual>
    <collision>
        <geometry>
          <cylinder radius="${chassis_radius}" length="${chassis_height}"/>
        </geometry>
    </collision>
    <inertial>
      <origin xyz="0 0 0"/>
      <mass value="1.0"/>
      <inertia ixx="0.1" ixy="0.0" ixz="0.0" iyy="0.1" iyz="0.0" izz="0.1"/>
    </inertial>
  </link>

<gazebo reference="chassis">
    <material>Gazebo/White</material>
</gazebo>

<!-- BASE_FOOTPRINT LINK

<joint name="base_footprint_joint" type="fixed">
  <parent link="base_link"/>
  <child link="base_footprint"/>
  <origin xyz ="0 0 0" rpy="0 0 0"/>
</joint>
 -->

  <!-- Controlled Wheels -->
  <xacro:macro name="wheel" params="name x y w">
    <link name="${name}">
      <visual>
        <geometry>
          <cylinder radius="${wheel_radius}" length="${wheel_width}"/>
        </geometry>
      </visual>
      <collision>
        <geometry>
          <cylinder radius="${wheel_radius}" length="${wheel_width}"/>
        </geometry>
      </collision>
      <inertial>
        <origin xyz="0 0 0"/>
        <mass value="0.1"/>
        <inertia ixx="0.001" ixy="0.0" ixz="0.0" iyy="0.001" iyz="0.0" izz="0.001"/>
      </inertial>
    </link>
    
    <joint name="${name}_joint" type="continuous">
      <parent link="base_link"/>
      <child link="${name}"/>
      <origin xyz="${x} ${y} 0" rpy="${w} 1.570795 0"/> <!-- Updated origin and rpy values -->
      <axis xyz="0 0 1"/> <!-- Updated axis definition -->
    </joint>
  </xacro:macro>

  <!-- Instantiate the wheels -->
  <xacro:wheel name="left_wheel" x="0" y="${chassis_radius}" w="-1.570795"/>
  <xacro:wheel name="right_wheel" x="0" y="-${chassis_radius}" w="-1.570795"/>

  <!-- Caster Wheel for Stability -->
  <link name="caster_wheel">
    <visual>
      <geometry>
        <sphere radius="0.03"/> <!-- Smaller sphere for simplicity -->
      </geometry>
    </visual>
    <collision>
      <geometry>
        <sphere radius="0.03"/>
      </geometry>
    </collision>
    <inertial>
      <origin xyz="0 0 0"/>
      <mass value="0.3"/>
      <inertia ixx="0.0001" ixy="0.0" ixz="0.0" iyy="0.0001" iyz="0.0" izz="0.0001"/>
    </inertial>
  </link>

<gazebo reference="caster_wheel">
    <material>Gazebo/Black</material>
    <mu1 value="0.001"/>
    <mu2 value="0.001"/>
</gazebo>

  <joint name="caster_joint" type="fixed">
    <parent link="base_link"/>
    <child link="caster_wheel"/>
    <origin xyz="0.2 0 -0.05" rpy="0 0 0"/>
  </joint>



</robot>
